<?xml version="1.0" ?>
<!-- =================================================================================== -->
<!-- |    This document was autogenerated by xacro from /home/philb/catkin_ws/src/spinner_description/urdf/spinner.urdf.xacro | -->
<!-- |    EDITING THIS FILE BY HAND IS NOT RECOMMENDED                                 | -->
<!-- =================================================================================== -->
<!-- Revolute-Revolute Manipulator -->
<robot name="spinner" xmlns:xacro="http://www.ros.org/wiki/xacro">
  <!-- Constants for robot dimensions -->
  <!-- arbitrary value for mass -->
  <!-- Square dimensions (widthxwidth) of beams -->
  <!-- Link 1 -->
  <!-- Link 2 -->
  <!-- Link 3 -->
  <!-- Size of square 'camera' box -->
  <!-- Space btw top of beam and the each joint -->
  <!-- Import all Gazebo-customization elements, including Gazebo colors -->
  <!-- ros_control plugin -->
  <gazebo>
    <plugin filename="libgazebo_ros_control.so" name="gazebo_ros_control">
      <robotNamespace>/spinner</robotNamespace>
      <robotSimType>gazebo_ros_control/DefaultRobotHWSim</robotSimType>
    </plugin>
  </gazebo>
  <!-- Base -->
  <gazebo reference="base">
    <material>Gazebo/Gold</material>
  </gazebo>
  <!-- Pole -->
  <gazebo reference="pole">
    <material>Gazebo/Blue</material>
  </gazebo>
  <!-- Arm -->
  <gazebo reference="arm">
    <material>Gazebo/Blue</material>
  </gazebo>
  <gazebo reference="blue_blk">
    <material>Gazebo/Blue</material>
  </gazebo>
  <gazebo reference="red_blk">
    <material>Gazebo/Red</material>
  </gazebo>
  <gazebo reference="yellow_blk">
    <material>Gazebo/Yellow</material>
  </gazebo>
  <gazebo reference="green_blk">
    <material>Gazebo/Green</material>
  </gazebo>
  <gazebo reference="black_blk">
    <material>Gazebo/Black</material>
  </gazebo>
  <gazebo reference="orange_blk">
    <material>Gazebo/Orange</material>
  </gazebo>
  <!-- Barrel -->
  <gazebo reference="barrel">
    <material>
      Gazebo/Black
          
      <!--script>
            <uri>package://spinner_description/materials/scripts</uri>
            <uri>package://spinner_description/materials/textures</uri-->
      <!--name>TexturedShape/Squares</name-->
      <!--name>TexturedShape/Barrel</name>
          </script-->
    </material>
  </gazebo>
  <!-- Camera -->
  <gazebo reference="camera_link">
    <material>Gazebo/Gray</material>
  </gazebo>
  <!-- camera -->
  <gazebo reference="camera_link">
    <sensor name="camera" type="camera">
      <always_on>1</always_on>
      <update_rate>10</update_rate>
      <visualize>true</visualize>
      <camera name="head">
        <horizontal_fov>1.05</horizontal_fov>
        <image>
          <width>320</width>
          <height>240</height>
          <format>R8G8B8</format>
        </image>
        <clip>
          <near>0.1</near>
          <far>3</far>
        </clip>
        <noise>
          <type>gaussian</type>
          <mean>0.0</mean>
          <stddev>0.007</stddev>
        </noise>
      </camera>
      <plugin filename="libgazebo_ros_camera.so" name="camera_controller">
        <alwaysOn>true</alwaysOn>
        <updateRate>10.0</updateRate>
        <cameraName>spinner/camera</cameraName>
        <imageTopicName>image_raw</imageTopicName>
        <cameraInfoTopicName>camera_info</cameraInfoTopicName>
        <frameName>camera_link</frameName>
        <hackBaseline>0.07</hackBaseline>
        <distortionK1>0.0</distortionK1>
        <distortionK2>0.0</distortionK2>
        <distortionK3>0.0</distortionK3>
        <distortionT1>0.0</distortionT1>
        <distortionT2>0.0</distortionT2>
      </plugin>
    </sensor>
  </gazebo>
  <!-- Import Rviz colors -->
  <material name="black">
    <color rgba="0.0 0.0 0.0 1.0"/>
  </material>
  <material name="blue">
    <color rgba="0.0 0.0 0.8 1.0"/>
  </material>
  <material name="green">
    <color rgba="0.0 0.8 0.0 1.0"/>
  </material>
  <material name="grey">
    <color rgba="0.2 0.2 0.2 1.0"/>
  </material>
  <material name="gold">
    <color rgba="1.0 0.843137254902 0.0 1.0"/>
  </material>
  <material name="orange">
    <color rgba="1.0 0.423529411765 0.0392156862745 1.0"/>
  </material>
  <material name="brown">
    <color rgba="0.870588235294 0.811764705882 0.764705882353 1.0"/>
  </material>
  <material name="red">
    <color rgba="0.8 0.0 0.0 1.0"/>
  </material>
  <material name="yellow">
    <color rgba="0.6 0.6 0.0 1.0"/>
  </material>
  <material name="white">
    <color rgba="1.0 1.0 1.0 1.0"/>
  </material>
  <material name="whorl">
    <texture filename="package://spinner_description/materials/textures/barrelgradient.png"/>
  </material>
  <material name="squares">
    <texture filename="package://spinner_description/materials/textures/squares.png"/>
  </material>
  <!-- Used for fixing robot to Gazebo 'base_link' -->
  <!--link name="world"/>

  <joint name="fixed" type="fixed">
    <parent link="world"/>
    <child link="base"/>
  </joint-->
  <link name="base">
    <collision>
      <origin rpy="0 0 0" xyz="0 0 0.01"/>
      <geometry>
        <cylinder length="0.02" radius="0.8"/>
      </geometry>
    </collision>
    <visual>
      <origin rpy="0 0 0" xyz="0 0 0.01"/>
      <geometry>
        <cylinder length="0.02" radius="0.8"/>
      </geometry>
      <material name="gold"/>
    </visual>
    <inertial>
      <origin rpy="0 0 0" xyz="0 0 0.01"/>
      <mass value="100"/>
      <inertia ixx="10" ixy="0.0" ixz="0.0" iyy="10" iyz="0.0" izz="10"/>
    </inertial>
  </link>
  <joint name="basepole" type="fixed">
    <parent link="base"/>
    <child link="pole"/>
  </joint>
  <link name="pole">
    <collision>
      <origin rpy="0 0 0" xyz="0 0 1.0"/>
      <geometry>
        <box size="0.1 0.1 2.0"/>
      </geometry>
    </collision>
    <visual>
      <origin rpy="0 0 0" xyz="0 0 1.0"/>
      <geometry>
        <box size="0.2 0.05 2.0"/>
      </geometry>
      <material name="blue"/>
    </visual>
    <inertial>
      <origin rpy="0 0 0" xyz="0 0 1.0"/>
      <mass value="1"/>
      <inertia ixx="1" ixy="0.0" ixz="0.0" iyy="1" iyz="0.0" izz="1"/>
    </inertial>
  </link>
  <!--limit effort="1000" lower="-1" upper="1" velocity="0.5"/-->
  <joint name="pancam" type="revolute">
    <parent link="pole"/>
    <child link="camera_link"/>
    <origin rpy="0 0 0" xyz="0 0 2.0"/>
    <axis xyz="0 0 1"/>
    <limit effort="1000" lower="-0.1" upper="0.1" velocity="0.5"/>
    <dynamics damping="0.7"/>
  </joint>
  <!--joint name="polecam" type="fixed">
    <parent link="pole"/>
    <child link="camera_link"/>
  </joint-->
  <link name="camera_link">
    <collision>
      <origin rpy="0 0 0" xyz="0 0 0"/>
      <geometry>
        <box size="0.1 0.1 0.1"/>
      </geometry>
    </collision>
    <visual>
      <origin rpy="0 0 0" xyz="0 0 0"/>
      <geometry>
        <box size="0.1 0.1 0.1"/>
      </geometry>
      <material name="grey"/>
    </visual>
    <inertial>
      <origin rpy="0 0 0" xyz="0 0 0"/>
      <mass value="0.01"/>
      <inertia ixx="1" ixy="0.0" ixz="0.0" iyy="1" iyz="0.0" izz="1"/>
    </inertial>
  </link>
  <link name="arm0">
    <collision>
      <origin rpy="0 0 0" xyz="0 0 0"/>
      <geometry>
        <box size="0.2 0.2 0.2"/>
      </geometry>
    </collision>
    <visual>
      <origin rpy="0 0 0" xyz="0 0 0.0"/>
      <geometry>
        <box size="0.2 0.2 0.2"/>
      </geometry>
      <material name="red"/>
    </visual>
    <inertial>
      <origin rpy="0 0 0" xyz="0 0 0"/>
      <mass value="1"/>
      <inertia ixx="1" ixy="0.0" ixz="0.0" iyy="1" iyz="0.0" izz="1"/>
    </inertial>
  </link>
  <!-- u joint for arm, at origin of upper link >
    <joint name="azimuth" type="revolute">
      <parent>base</parent>
      <child>arm0</child>
      <axis>
        <xyz>0 0 1</xyz>
        <use_parent_model_frame>false</use_parent_model_frame>
        <dynamics><damping>5.0</damping></dynamics>
	<limit><lower>-1</lower><upper>1</upper></limit>
      </axis>
    </joint>
    <joint name="elevation" type="revolute">
      <parent>arm0</parent>
      <child>arm1</child>
      <axis>
        <xyz>1 0 0</xyz>
        <use_parent_model_frame>false</use_parent_model_frame>
        <dynamics><damping>5.0</damping></dynamics>
	<limit><lower>-1</lower><upper>1</upper></limit>
      </axis>
    </joint-->
  <!--pin joint for barrel, at origin of child link>
    <joint name="spinner" type="revolute">
      <parent>arm1</parent>
      <child>barrel</child>
      <axis>
        <xyz>0 0 1</xyz>
        <use_parent_model_frame>false</use_parent_model_frame>
        <dynamics><damping>5.0</damping></dynamics>
	<limit><lower>-3.142</lower><upper>3.142</upper></limit>
      </axis>
    </joint-->
  <joint name="azimuth" type="continuous">
    <parent link="pole"/>
    <child link="arm0"/>
    <origin rpy="0 0 0" xyz="0 0 2.0"/>
    <axis xyz="0 0 1"/>
    <dynamics damping="10.0"/>
  </joint>
  <joint name="elevation" type="continuous">
    <parent link="arm0"/>
    <child link="arm"/>
    <origin rpy="0 0 0" xyz="0 0 0"/>
    <axis xyz="1 0 0"/>
    <dynamics damping="10.0"/>
  </joint>
  <joint name="spinner" type="continuous">
    <parent link="arm"/>
    <child link="barrel"/>
    <origin rpy="0 0 0" xyz="0 1.0 0"/>
    <axis xyz="0 0 1"/>
    <dynamics damping="1.0"/>
  </joint>
  <link name="arm">
    <collision>
      <origin rpy="-1.5708 0 0" xyz="0 0.5 0"/>
      <geometry>
        <cylinder length="1.0" radius="0.01"/>
      </geometry>
    </collision>
    <visual>
      <origin rpy="-1.5708 0 0" xyz="0 0.5 0"/>
      <geometry>
        <cylinder length="1.0" radius="0.01"/>
      </geometry>
      <material name="blue"/>
    </visual>
    <inertial>
      <origin rpy="-1.5708 0 0" xyz="0 0.5 0"/>
      <mass value="1"/>
      <inertia ixx="1" ixy="0.0" ixz="0.0" iyy="1" iyz="0.0" izz="1"/>
    </inertial>
  </link>
  <link name="barrel">
    <collision>
      <origin rpy="0 0 0" xyz="0 0 0.05"/>
      <geometry>
        <cylinder length="0.1" radius="0.5"/>
      </geometry>
    </collision>
    <visual>
      <origin rpy="0 0 0" xyz="0 0 0.05"/>
      <geometry>
        <cylinder length="0.1" radius="0.5"/>
      </geometry>
      <!--material name="orange"/-->
      <material name="whorl"/>
    </visual>
    <inertial>
      <origin rpy="0 0 0" xyz="0 0 0.05"/>
      <mass value="1"/>
      <inertia ixx="1" ixy="0.0" ixz="0.0" iyy="1" iyz="0.0" izz="1"/>
    </inertial>
  </link>
  <link name="blue_blk">
    <collision>
      <geometry>
        <box size="0.1 0.1 0.1"/>
      </geometry>
    </collision>
    <visual>
      <geometry>
        <box size="0.1 0.1 0.1"/>
      </geometry>
      <material name="blue"/>
    </visual>
    <inertial>
      <mass value="0.01"/>
      <inertia ixx="1" ixy="0.0" ixz="0.0" iyy="1" iyz="0.0" izz="1"/>
    </inertial>
  </link>
  <joint name="blue_jt" type="fixed">
    <parent link="barrel"/>
    <child link="blue_blk"/>
    <origin rpy="0 0 0" xyz="0.5 0 0"/>
  </joint>
  <link name="red_blk">
    <collision>
      <geometry>
        <box size="0.1 0.1 0.1"/>
      </geometry>
    </collision>
    <visual>
      <geometry>
        <box size="0.1 0.1 0.1"/>
      </geometry>
      <material name="red"/>
    </visual>
    <inertial>
      <mass value="0.01"/>
      <inertia ixx="1" ixy="0.0" ixz="0.0" iyy="1" iyz="0.0" izz="1"/>
    </inertial>
  </link>
  <joint name="red_jt" type="fixed">
    <parent link="barrel"/>
    <child link="red_blk"/>
    <origin rpy="0 0 0" xyz="0.25 0.42 0"/>
  </joint>
  <link name="yellow_blk">
    <collision>
      <geometry>
        <box size="0.1 0.1 0.1"/>
      </geometry>
    </collision>
    <visual>
      <geometry>
        <box size="0.1 0.1 0.1"/>
      </geometry>
      <material name="yellow"/>
    </visual>
    <inertial>
      <mass value="0.01"/>
      <inertia ixx="1" ixy="0.0" ixz="0.0" iyy="1" iyz="0.0" izz="1"/>
    </inertial>
  </link>
  <joint name="yellow_jt" type="fixed">
    <parent link="barrel"/>
    <child link="yellow_blk"/>
    <origin rpy="0 0 0" xyz="-0.25 0.42 0"/>
  </joint>
  <link name="green_blk">
    <collision>
      <geometry>
        <box size="0.1 0.1 0.1"/>
      </geometry>
    </collision>
    <visual>
      <geometry>
        <box size="0.1 0.1 0.1"/>
      </geometry>
      <material name="green"/>
    </visual>
    <inertial>
      <mass value="0.01"/>
      <inertia ixx="1" ixy="0.0" ixz="0.0" iyy="1" iyz="0.0" izz="1"/>
    </inertial>
  </link>
  <joint name="green_jt" type="fixed">
    <parent link="barrel"/>
    <child link="green_blk"/>
    <origin rpy="0 0 0" xyz="-0.5 0 0"/>
  </joint>
  <link name="black_blk">
    <collision>
      <geometry>
        <box size="0.1 0.1 0.1"/>
      </geometry>
    </collision>
    <visual>
      <geometry>
        <box size="0.1 0.1 0.1"/>
      </geometry>
      <material name="black"/>
    </visual>
    <inertial>
      <mass value="0.01"/>
      <inertia ixx="1" ixy="0.0" ixz="0.0" iyy="1" iyz="0.0" izz="1"/>
    </inertial>
  </link>
  <joint name="black_jt" type="fixed">
    <parent link="barrel"/>
    <child link="black_blk"/>
    <origin rpy="0 0 0" xyz="-0.25 -0.42 0"/>
  </joint>
  <link name="orange_blk">
    <collision>
      <geometry>
        <box size="0.1 0.1 0.1"/>
      </geometry>
    </collision>
    <visual>
      <geometry>
        <box size="0.1 0.1 0.1"/>
      </geometry>
      <material name="orange"/>
    </visual>
    <inertial>
      <mass value="0.01"/>
      <inertia ixx="1" ixy="0.0" ixz="0.0" iyy="1" iyz="0.0" izz="1"/>
    </inertial>
  </link>
  <joint name="orange_jt" type="fixed">
    <parent link="barrel"/>
    <child link="orange_blk"/>
    <origin rpy="0 0 0" xyz="0.25 -0.42 0"/>
  </joint>
</robot>
